[2024-05-12 23:39:20,025] ERROR exception() L268  Exception in worker process - call_trace=/usr/local/lib/python3.11/site-packages/gunicorn/glogging.py L268 
Traceback (most recent call last):
  File "/usr/local/lib/python3.11/site-packages/gunicorn/arbiter.py", line 583, in spawn_worker
    worker.init_process()
  File "/usr/local/lib/python3.11/site-packages/gunicorn/workers/base.py", line 119, in init_process
    self.load_wsgi()
  File "/usr/local/lib/python3.11/site-packages/gunicorn/workers/base.py", line 144, in load_wsgi
    self.wsgi = self.app.wsgi()
                ^^^^^^^^^^^^^^^
  File "/usr/local/lib/python3.11/site-packages/gunicorn/app/base.py", line 67, in wsgi
    self.callable = self.load()
                    ^^^^^^^^^^^
  File "/usr/local/lib/python3.11/site-packages/gunicorn/app/wsgiapp.py", line 49, in load
    return self.load_wsgiapp()
           ^^^^^^^^^^^^^^^^^^^
  File "/usr/local/lib/python3.11/site-packages/gunicorn/app/wsgiapp.py", line 39, in load_wsgiapp
    return util.import_app(self.app_uri)
           ^^^^^^^^^^^^^^^^^^^^^^^^^^^^^
  File "/usr/local/lib/python3.11/site-packages/gunicorn/util.py", line 358, in import_app
    mod = importlib.import_module(module)
          ^^^^^^^^^^^^^^^^^^^^^^^^^^^^^^^
  File "/usr/local/lib/python3.11/importlib/__init__.py", line 126, in import_module
    return _bootstrap._gcd_import(name[level:], package, level)
           ^^^^^^^^^^^^^^^^^^^^^^^^^^^^^^^^^^^^^^^^^^^^^^^^^^^^
  File "<frozen importlib._bootstrap>", line 1206, in _gcd_import
  File "<frozen importlib._bootstrap>", line 1178, in _find_and_load
  File "<frozen importlib._bootstrap>", line 1149, in _find_and_load_unlocked
  File "<frozen importlib._bootstrap>", line 690, in _load_unlocked
  File "<frozen importlib._bootstrap_external>", line 940, in exec_module
  File "<frozen importlib._bootstrap>", line 241, in _call_with_frames_removed
  File "/app/wsgi.py", line 10, in <module>
    application = create_app('config.default.' + APP_ENV)
                  ^^^^^^^^^^^^^^^^^^^^^^^^^^^^^^^^^^^^^^^
TypeError: create_app() takes 0 positional arguments but 1 was given
[2024-05-12 23:39:20,026] INFO info() L262  Worker exiting (pid: 8) - call_trace=/usr/local/lib/python3.11/site-packages/gunicorn/glogging.py L262 
[2024-05-12 23:39:31,019] ERROR exception() L268  Exception in worker process - call_trace=/usr/local/lib/python3.11/site-packages/gunicorn/glogging.py L268 
Traceback (most recent call last):
  File "/usr/local/lib/python3.11/site-packages/gunicorn/arbiter.py", line 583, in spawn_worker
    worker.init_process()
  File "/usr/local/lib/python3.11/site-packages/gunicorn/workers/base.py", line 119, in init_process
    self.load_wsgi()
  File "/usr/local/lib/python3.11/site-packages/gunicorn/workers/base.py", line 144, in load_wsgi
    self.wsgi = self.app.wsgi()
                ^^^^^^^^^^^^^^^
  File "/usr/local/lib/python3.11/site-packages/gunicorn/app/base.py", line 67, in wsgi
    self.callable = self.load()
                    ^^^^^^^^^^^
  File "/usr/local/lib/python3.11/site-packages/gunicorn/app/wsgiapp.py", line 49, in load
    return self.load_wsgiapp()
           ^^^^^^^^^^^^^^^^^^^
  File "/usr/local/lib/python3.11/site-packages/gunicorn/app/wsgiapp.py", line 39, in load_wsgiapp
    return util.import_app(self.app_uri)
           ^^^^^^^^^^^^^^^^^^^^^^^^^^^^^
  File "/usr/local/lib/python3.11/site-packages/gunicorn/util.py", line 358, in import_app
    mod = importlib.import_module(module)
          ^^^^^^^^^^^^^^^^^^^^^^^^^^^^^^^
  File "/usr/local/lib/python3.11/importlib/__init__.py", line 126, in import_module
    return _bootstrap._gcd_import(name[level:], package, level)
           ^^^^^^^^^^^^^^^^^^^^^^^^^^^^^^^^^^^^^^^^^^^^^^^^^^^^
  File "<frozen importlib._bootstrap>", line 1206, in _gcd_import
  File "<frozen importlib._bootstrap>", line 1178, in _find_and_load
  File "<frozen importlib._bootstrap>", line 1149, in _find_and_load_unlocked
  File "<frozen importlib._bootstrap>", line 690, in _load_unlocked
  File "<frozen importlib._bootstrap_external>", line 940, in exec_module
  File "<frozen importlib._bootstrap>", line 241, in _call_with_frames_removed
  File "/app/wsgi.py", line 10, in <module>
    application = create_app()
                  ^^^^^^^^^^^^
  File "/app/app.py", line 9, in create_app
    CORS(app)
  File "/usr/local/lib/python3.11/site-packages/flask_cors/__init__.py", line 235, in __init__
    self.init_app(app, **kwargs)
  File "/usr/local/lib/python3.11/site-packages/flask_cors/__init__.py", line 245, in init_app
    resources = _parse_resources(options.get('resources', [r'/*']))
                ^^^^^^^^^^^^^^^^^^^^^^^^^^^^^^^^^^^^^^^^^^^^^^^^^^^
  File "/usr/local/lib/python3.11/site-packages/flask_cors/__init__.py", line 308, in _parse_resources
    elif isinstance(resources, collections.Iterable):
                               ^^^^^^^^^^^^^^^^^^^^
AttributeError: module 'collections' has no attribute 'Iterable'
[2024-05-12 23:39:31,020] INFO info() L262  Worker exiting (pid: 8) - call_trace=/usr/local/lib/python3.11/site-packages/gunicorn/glogging.py L262 
[2024-05-13 00:03:25,952] INFO info() L262  Worker exiting (pid: 8) - call_trace=/usr/local/lib/python3.11/site-packages/gunicorn/glogging.py L262 
[2024-05-13 00:03:31,017] ERROR exception() L268  Exception in worker process - call_trace=/usr/local/lib/python3.11/site-packages/gunicorn/glogging.py L268 
Traceback (most recent call last):
  File "/usr/local/lib/python3.11/site-packages/gunicorn/arbiter.py", line 583, in spawn_worker
    worker.init_process()
  File "/usr/local/lib/python3.11/site-packages/gunicorn/workers/base.py", line 119, in init_process
    self.load_wsgi()
  File "/usr/local/lib/python3.11/site-packages/gunicorn/workers/base.py", line 144, in load_wsgi
    self.wsgi = self.app.wsgi()
                ^^^^^^^^^^^^^^^
  File "/usr/local/lib/python3.11/site-packages/gunicorn/app/base.py", line 67, in wsgi
    self.callable = self.load()
                    ^^^^^^^^^^^
  File "/usr/local/lib/python3.11/site-packages/gunicorn/app/wsgiapp.py", line 49, in load
    return self.load_wsgiapp()
           ^^^^^^^^^^^^^^^^^^^
  File "/usr/local/lib/python3.11/site-packages/gunicorn/app/wsgiapp.py", line 39, in load_wsgiapp
    return util.import_app(self.app_uri)
           ^^^^^^^^^^^^^^^^^^^^^^^^^^^^^
  File "/usr/local/lib/python3.11/site-packages/gunicorn/util.py", line 358, in import_app
    mod = importlib.import_module(module)
          ^^^^^^^^^^^^^^^^^^^^^^^^^^^^^^^
  File "/usr/local/lib/python3.11/importlib/__init__.py", line 126, in import_module
    return _bootstrap._gcd_import(name[level:], package, level)
           ^^^^^^^^^^^^^^^^^^^^^^^^^^^^^^^^^^^^^^^^^^^^^^^^^^^^
  File "<frozen importlib._bootstrap>", line 1206, in _gcd_import
  File "<frozen importlib._bootstrap>", line 1178, in _find_and_load
  File "<frozen importlib._bootstrap>", line 1149, in _find_and_load_unlocked
  File "<frozen importlib._bootstrap>", line 690, in _load_unlocked
  File "<frozen importlib._bootstrap_external>", line 940, in exec_module
  File "<frozen importlib._bootstrap>", line 241, in _call_with_frames_removed
  File "/app/wsgi.py", line 10, in <module>
    application = create_app()
                  ^^^^^^^^^^^^
  File "/app/app.py", line 11, in create_app
    produtos.register_endpoint.configure(app)
    ^^^^^^^^^^^^^^^^^^^^^^^^^^^^^^^^^^^^
AttributeError: 'function' object has no attribute 'configure'
[2024-05-13 00:03:31,018] INFO info() L262  Worker exiting (pid: 8) - call_trace=/usr/local/lib/python3.11/site-packages/gunicorn/glogging.py L262 
[2024-05-13 00:09:20,245] INFO info() L262  Worker exiting (pid: 8) - call_trace=/usr/local/lib/python3.11/site-packages/gunicorn/glogging.py L262 
[2024-05-13 00:10:38,499] INFO info() L262  Worker exiting (pid: 8) - call_trace=/usr/local/lib/python3.11/site-packages/gunicorn/glogging.py L262 
[2024-05-13 00:12:21,842] INFO info() L262  Worker exiting (pid: 8) - call_trace=/usr/local/lib/python3.11/site-packages/gunicorn/glogging.py L262 
[2024-05-13 00:21:43,204] INFO info() L262  Worker exiting (pid: 8) - call_trace=/usr/local/lib/python3.11/site-packages/gunicorn/glogging.py L262 
[2024-05-13 00:23:16,142] INFO info() L262  Worker exiting (pid: 8) - call_trace=/usr/local/lib/python3.11/site-packages/gunicorn/glogging.py L262 
[2024-05-13 00:24:35,127] INFO info() L262  Worker exiting (pid: 7) - call_trace=/usr/local/lib/python3.11/site-packages/gunicorn/glogging.py L262 
[2024-05-13 00:29:46,148] INFO info() L262  Worker exiting (pid: 7) - call_trace=/usr/local/lib/python3.11/site-packages/gunicorn/glogging.py L262 
